10/07/24 (02:05:26) | ERROR: Data collection thread failed with exception: Sign not allowed in string format specifier
Traceback (most recent call last):
  File "/usr/bin/bpytop", line 2959, in _runner
    collector._draw()
  File "/usr/bin/bpytop", line 3991, in _draw
    ProcBox._draw_fg()
  File "/usr/bin/bpytop", line 2739, in _draw_fg
    label = (f'{THEME.title}{Fx.b}{Mv.to(y, x)}{"Pid:":>7} {"Program:" if prog_len > 8 else "Prg:":<{prog_len}}' + (f'{"Arguments:":<{arg_len-4}}' if arg_len else "") +
                                                           ^^^^^^^^^^^^^^^^^^^^^^^^^^^^^^^^^^^^^^^^^^^^^^^^^^^^
ValueError: Sign not allowed in string format specifier
10/07/24 (02:05:26) | WARNING: Exiting with errorcode (1). Runtime 0:00:00 

10/07/24 (02:06:06) | ERROR: Data collection thread failed with exception: Sign not allowed in string format specifier
Traceback (most recent call last):
  File "/usr/bin/bpytop", line 2959, in _runner
    collector._draw()
  File "/usr/bin/bpytop", line 3991, in _draw
    ProcBox._draw_fg()
  File "/usr/bin/bpytop", line 2739, in _draw_fg
    label = (f'{THEME.title}{Fx.b}{Mv.to(y, x)}{"Pid:":>7} {"Program:" if prog_len > 8 else "Prg:":<{prog_len}}' + (f'{"Arguments:":<{arg_len-4}}' if arg_len else "") +
                                                           ^^^^^^^^^^^^^^^^^^^^^^^^^^^^^^^^^^^^^^^^^^^^^^^^^^^^
ValueError: Sign not allowed in string format specifier
10/07/24 (02:06:06) | WARNING: Exiting with errorcode (1). Runtime 0:00:00 

10/07/24 (02:07:28) | WARNING: No theme named "+greyscale" found!
10/07/24 (02:07:28) | ERROR: Data collection thread failed with exception: list index out of range
Traceback (most recent call last):
  File "/usr/bin/bpytop", line 2959, in _runner
    collector._draw()
  File "/usr/bin/bpytop", line 3991, in _draw
    ProcBox._draw_fg()
  File "/usr/bin/bpytop", line 2835, in _draw_fg
    vals += [f'{THEME.gradient["proc_color" if val < 100 else "process"][val if val < 100 else val - 100]}']
                ~~~~~~~~~~~~~~~~~~~~~~~~~~~~~~~~~~~~~~~~~~~~~~~~~~~~~~~~^^^^^^^^^^^^^^^^^^^^^^^^^^^^^^^^^
IndexError: list index out of range
10/07/24 (02:07:28) | WARNING: Exiting with errorcode (1). Runtime 0:00:00 

10/07/24 (02:08:18) | WARNING: No theme named "+greyscale" found!
10/07/24 (02:08:18) | ERROR: Data collection thread failed with exception: Sign not allowed in string format specifier
Traceback (most recent call last):
  File "/usr/bin/bpytop", line 2959, in _runner
    collector._draw()
  File "/usr/bin/bpytop", line 3991, in _draw
    ProcBox._draw_fg()
  File "/usr/bin/bpytop", line 2739, in _draw_fg
    label = (f'{THEME.title}{Fx.b}{Mv.to(y, x)}{"Pid:":>7} {"Program:" if prog_len > 8 else "Prg:":<{prog_len}}' + (f'{"Arguments:":<{arg_len-4}}' if arg_len else "") +
                                                           ^^^^^^^^^^^^^^^^^^^^^^^^^^^^^^^^^^^^^^^^^^^^^^^^^^^^
ValueError: Sign not allowed in string format specifier
10/07/24 (02:08:18) | WARNING: Exiting with errorcode (1). Runtime 0:00:00 

10/07/24 (02:08:31) | WARNING: No theme named "+greyscale" found!
10/07/24 (02:09:48) | WARNING: No theme named "+greyscale" found!
10/07/24 (02:10:22) | ERROR: division by zero
Traceback (most recent call last):
  File "/usr/bin/bpytop", line 5677, in main
    run()
  File "/usr/bin/bpytop", line 5671, in run
    process_keys()
  File "/usr/bin/bpytop", line 5445, in process_keys
    Term.refresh(force=True)
  File "/usr/bin/bpytop", line 732, in refresh
    Box.calc_sizes()
  File "/usr/bin/bpytop", line 1705, in calc_sizes
    sub._calc_size() # type: ignore
    ^^^^^^^^^^^^^^^^
  File "/usr/bin/bpytop", line 1842, in _calc_size
    cls.box_height = ceil(THREADS / cls.box_columns) + 4
                          ~~~~~~~~^~~~~~~~~~~~~~~~~
ZeroDivisionError: division by zero
10/07/24 (02:10:22) | WARNING: Exiting with errorcode (1). Runtime 0:00:02 

13/07/24 (15:57:58) | ERROR: <urlopen error [Errno -2] Name or service not known>
Traceback (most recent call last):
  File "/usr/lib/python3.12/urllib/request.py", line 1344, in do_open
    h.request(req.get_method(), req.selector, req.data, headers,
  File "/usr/lib/python3.12/http/client.py", line 1336, in request
    self._send_request(method, url, body, headers, encode_chunked)
  File "/usr/lib/python3.12/http/client.py", line 1382, in _send_request
    self.endheaders(body, encode_chunked=encode_chunked)
  File "/usr/lib/python3.12/http/client.py", line 1331, in endheaders
    self._send_output(message_body, encode_chunked=encode_chunked)
  File "/usr/lib/python3.12/http/client.py", line 1091, in _send_output
    self.send(msg)
  File "/usr/lib/python3.12/http/client.py", line 1035, in send
    self.connect()
  File "/usr/lib/python3.12/http/client.py", line 1470, in connect
    super().connect()
  File "/usr/lib/python3.12/http/client.py", line 1001, in connect
    self.sock = self._create_connection(
                ^^^^^^^^^^^^^^^^^^^^^^^^
  File "/usr/lib/python3.12/socket.py", line 829, in create_connection
    for res in getaddrinfo(host, port, 0, SOCK_STREAM):
               ^^^^^^^^^^^^^^^^^^^^^^^^^^^^^^^^^^^^^^^
  File "/usr/lib/python3.12/socket.py", line 964, in getaddrinfo
    for res in _socket.getaddrinfo(host, port, family, type, proto, flags):
               ^^^^^^^^^^^^^^^^^^^^^^^^^^^^^^^^^^^^^^^^^^^^^^^^^^^^^^^^^^^
socket.gaierror: [Errno -2] Name or service not known

During handling of the above exception, another exception occurred:

Traceback (most recent call last):
  File "/usr/bin/bpytop", line 5029, in _checker
    with urllib.request.urlopen("https://github.com/aristocratos/bpytop/raw/master/bpytop.py", timeout=5) as source: # type: ignore
         ^^^^^^^^^^^^^^^^^^^^^^^^^^^^^^^^^^^^^^^^^^^^^^^^^^^^^^^^^^^^^^^^^^^^^^^^^^^^^^^^^^^^^^^^^^^^^^^^
  File "/usr/lib/python3.12/urllib/request.py", line 215, in urlopen
    return opener.open(url, data, timeout)
           ^^^^^^^^^^^^^^^^^^^^^^^^^^^^^^^
  File "/usr/lib/python3.12/urllib/request.py", line 515, in open
    response = self._open(req, data)
               ^^^^^^^^^^^^^^^^^^^^^
  File "/usr/lib/python3.12/urllib/request.py", line 532, in _open
    result = self._call_chain(self.handle_open, protocol, protocol +
             ^^^^^^^^^^^^^^^^^^^^^^^^^^^^^^^^^^^^^^^^^^^^^^^^^^^^^^^
  File "/usr/lib/python3.12/urllib/request.py", line 492, in _call_chain
    result = func(*args)
             ^^^^^^^^^^^
  File "/usr/lib/python3.12/urllib/request.py", line 1392, in https_open
    return self.do_open(http.client.HTTPSConnection, req,
           ^^^^^^^^^^^^^^^^^^^^^^^^^^^^^^^^^^^^^^^^^^^^^^
  File "/usr/lib/python3.12/urllib/request.py", line 1347, in do_open
    raise URLError(err)
urllib.error.URLError: <urlopen error [Errno -2] Name or service not known>
14/07/24 (21:44:57) | ERROR: <urlopen error [Errno -2] Name or service not known>
Traceback (most recent call last):
  File "/usr/lib/python3.12/urllib/request.py", line 1344, in do_open
    h.request(req.get_method(), req.selector, req.data, headers,
  File "/usr/lib/python3.12/http/client.py", line 1336, in request
    self._send_request(method, url, body, headers, encode_chunked)
  File "/usr/lib/python3.12/http/client.py", line 1382, in _send_request
    self.endheaders(body, encode_chunked=encode_chunked)
  File "/usr/lib/python3.12/http/client.py", line 1331, in endheaders
    self._send_output(message_body, encode_chunked=encode_chunked)
  File "/usr/lib/python3.12/http/client.py", line 1091, in _send_output
    self.send(msg)
  File "/usr/lib/python3.12/http/client.py", line 1035, in send
    self.connect()
  File "/usr/lib/python3.12/http/client.py", line 1470, in connect
    super().connect()
  File "/usr/lib/python3.12/http/client.py", line 1001, in connect
    self.sock = self._create_connection(
                ^^^^^^^^^^^^^^^^^^^^^^^^
  File "/usr/lib/python3.12/socket.py", line 829, in create_connection
    for res in getaddrinfo(host, port, 0, SOCK_STREAM):
               ^^^^^^^^^^^^^^^^^^^^^^^^^^^^^^^^^^^^^^^
  File "/usr/lib/python3.12/socket.py", line 964, in getaddrinfo
    for res in _socket.getaddrinfo(host, port, family, type, proto, flags):
               ^^^^^^^^^^^^^^^^^^^^^^^^^^^^^^^^^^^^^^^^^^^^^^^^^^^^^^^^^^^
socket.gaierror: [Errno -2] Name or service not known

During handling of the above exception, another exception occurred:

Traceback (most recent call last):
  File "/usr/bin/bpytop", line 5029, in _checker
    with urllib.request.urlopen("https://github.com/aristocratos/bpytop/raw/master/bpytop.py", timeout=5) as source: # type: ignore
         ^^^^^^^^^^^^^^^^^^^^^^^^^^^^^^^^^^^^^^^^^^^^^^^^^^^^^^^^^^^^^^^^^^^^^^^^^^^^^^^^^^^^^^^^^^^^^^^^
  File "/usr/lib/python3.12/urllib/request.py", line 215, in urlopen
    return opener.open(url, data, timeout)
           ^^^^^^^^^^^^^^^^^^^^^^^^^^^^^^^
  File "/usr/lib/python3.12/urllib/request.py", line 515, in open
    response = self._open(req, data)
               ^^^^^^^^^^^^^^^^^^^^^
  File "/usr/lib/python3.12/urllib/request.py", line 532, in _open
    result = self._call_chain(self.handle_open, protocol, protocol +
             ^^^^^^^^^^^^^^^^^^^^^^^^^^^^^^^^^^^^^^^^^^^^^^^^^^^^^^^
  File "/usr/lib/python3.12/urllib/request.py", line 492, in _call_chain
    result = func(*args)
             ^^^^^^^^^^^
  File "/usr/lib/python3.12/urllib/request.py", line 1392, in https_open
    return self.do_open(http.client.HTTPSConnection, req,
           ^^^^^^^^^^^^^^^^^^^^^^^^^^^^^^^^^^^^^^^^^^^^^^
  File "/usr/lib/python3.12/urllib/request.py", line 1347, in do_open
    raise URLError(err)
urllib.error.URLError: <urlopen error [Errno -2] Name or service not known>
15/07/24 (13:56:05) | ERROR: <urlopen error [Errno -2] Name or service not known>
Traceback (most recent call last):
  File "/usr/lib/python3.12/urllib/request.py", line 1344, in do_open
    h.request(req.get_method(), req.selector, req.data, headers,
  File "/usr/lib/python3.12/http/client.py", line 1336, in request
    self._send_request(method, url, body, headers, encode_chunked)
  File "/usr/lib/python3.12/http/client.py", line 1382, in _send_request
    self.endheaders(body, encode_chunked=encode_chunked)
  File "/usr/lib/python3.12/http/client.py", line 1331, in endheaders
    self._send_output(message_body, encode_chunked=encode_chunked)
  File "/usr/lib/python3.12/http/client.py", line 1091, in _send_output
    self.send(msg)
  File "/usr/lib/python3.12/http/client.py", line 1035, in send
    self.connect()
  File "/usr/lib/python3.12/http/client.py", line 1470, in connect
    super().connect()
  File "/usr/lib/python3.12/http/client.py", line 1001, in connect
    self.sock = self._create_connection(
                ^^^^^^^^^^^^^^^^^^^^^^^^
  File "/usr/lib/python3.12/socket.py", line 829, in create_connection
    for res in getaddrinfo(host, port, 0, SOCK_STREAM):
               ^^^^^^^^^^^^^^^^^^^^^^^^^^^^^^^^^^^^^^^
  File "/usr/lib/python3.12/socket.py", line 964, in getaddrinfo
    for res in _socket.getaddrinfo(host, port, family, type, proto, flags):
               ^^^^^^^^^^^^^^^^^^^^^^^^^^^^^^^^^^^^^^^^^^^^^^^^^^^^^^^^^^^
socket.gaierror: [Errno -2] Name or service not known

During handling of the above exception, another exception occurred:

Traceback (most recent call last):
  File "/usr/bin/bpytop", line 5029, in _checker
    with urllib.request.urlopen("https://github.com/aristocratos/bpytop/raw/master/bpytop.py", timeout=5) as source: # type: ignore
         ^^^^^^^^^^^^^^^^^^^^^^^^^^^^^^^^^^^^^^^^^^^^^^^^^^^^^^^^^^^^^^^^^^^^^^^^^^^^^^^^^^^^^^^^^^^^^^^^
  File "/usr/lib/python3.12/urllib/request.py", line 215, in urlopen
    return opener.open(url, data, timeout)
           ^^^^^^^^^^^^^^^^^^^^^^^^^^^^^^^
  File "/usr/lib/python3.12/urllib/request.py", line 515, in open
    response = self._open(req, data)
               ^^^^^^^^^^^^^^^^^^^^^
  File "/usr/lib/python3.12/urllib/request.py", line 532, in _open
    result = self._call_chain(self.handle_open, protocol, protocol +
             ^^^^^^^^^^^^^^^^^^^^^^^^^^^^^^^^^^^^^^^^^^^^^^^^^^^^^^^
  File "/usr/lib/python3.12/urllib/request.py", line 492, in _call_chain
    result = func(*args)
             ^^^^^^^^^^^
  File "/usr/lib/python3.12/urllib/request.py", line 1392, in https_open
    return self.do_open(http.client.HTTPSConnection, req,
           ^^^^^^^^^^^^^^^^^^^^^^^^^^^^^^^^^^^^^^^^^^^^^^
  File "/usr/lib/python3.12/urllib/request.py", line 1347, in do_open
    raise URLError(err)
urllib.error.URLError: <urlopen error [Errno -2] Name or service not known>
15/07/24 (20:29:37) | ERROR: Data collection thread failed with exception: Precision not allowed in integer format specifier
Traceback (most recent call last):
  File "/usr/bin/bpytop", line 2959, in _runner
    collector._draw()
  File "/usr/bin/bpytop", line 3991, in _draw
    ProcBox._draw_fg()
  File "/usr/bin/bpytop", line 2771, in _draw_fg
    (f'{proc.details["threads"]:^{iw}.{iw2}}' if expand > 0 else "") + (f'{proc.details["nice"]:^{iw}.{iw2}}' if expand > 1 else "") +
                                                                          ^^^^^^^^^^^^^^^^^^^^^^^^^^^^^^^^^^
ValueError: Precision not allowed in integer format specifier
17/07/24 (16:06:52) | ERROR: <urlopen error [Errno -2] Name or service not known>
Traceback (most recent call last):
  File "/usr/lib/python3.12/urllib/request.py", line 1344, in do_open
    h.request(req.get_method(), req.selector, req.data, headers,
  File "/usr/lib/python3.12/http/client.py", line 1336, in request
    self._send_request(method, url, body, headers, encode_chunked)
  File "/usr/lib/python3.12/http/client.py", line 1382, in _send_request
    self.endheaders(body, encode_chunked=encode_chunked)
  File "/usr/lib/python3.12/http/client.py", line 1331, in endheaders
    self._send_output(message_body, encode_chunked=encode_chunked)
  File "/usr/lib/python3.12/http/client.py", line 1091, in _send_output
    self.send(msg)
  File "/usr/lib/python3.12/http/client.py", line 1035, in send
    self.connect()
  File "/usr/lib/python3.12/http/client.py", line 1470, in connect
    super().connect()
  File "/usr/lib/python3.12/http/client.py", line 1001, in connect
    self.sock = self._create_connection(
                ^^^^^^^^^^^^^^^^^^^^^^^^
  File "/usr/lib/python3.12/socket.py", line 829, in create_connection
    for res in getaddrinfo(host, port, 0, SOCK_STREAM):
               ^^^^^^^^^^^^^^^^^^^^^^^^^^^^^^^^^^^^^^^
  File "/usr/lib/python3.12/socket.py", line 964, in getaddrinfo
    for res in _socket.getaddrinfo(host, port, family, type, proto, flags):
               ^^^^^^^^^^^^^^^^^^^^^^^^^^^^^^^^^^^^^^^^^^^^^^^^^^^^^^^^^^^
socket.gaierror: [Errno -2] Name or service not known

During handling of the above exception, another exception occurred:

Traceback (most recent call last):
  File "/usr/bin/bpytop", line 5029, in _checker
    with urllib.request.urlopen("https://github.com/aristocratos/bpytop/raw/master/bpytop.py", timeout=5) as source: # type: ignore
         ^^^^^^^^^^^^^^^^^^^^^^^^^^^^^^^^^^^^^^^^^^^^^^^^^^^^^^^^^^^^^^^^^^^^^^^^^^^^^^^^^^^^^^^^^^^^^^^^
  File "/usr/lib/python3.12/urllib/request.py", line 215, in urlopen
    return opener.open(url, data, timeout)
           ^^^^^^^^^^^^^^^^^^^^^^^^^^^^^^^
  File "/usr/lib/python3.12/urllib/request.py", line 515, in open
    response = self._open(req, data)
               ^^^^^^^^^^^^^^^^^^^^^
  File "/usr/lib/python3.12/urllib/request.py", line 532, in _open
    result = self._call_chain(self.handle_open, protocol, protocol +
             ^^^^^^^^^^^^^^^^^^^^^^^^^^^^^^^^^^^^^^^^^^^^^^^^^^^^^^^
  File "/usr/lib/python3.12/urllib/request.py", line 492, in _call_chain
    result = func(*args)
             ^^^^^^^^^^^
  File "/usr/lib/python3.12/urllib/request.py", line 1392, in https_open
    return self.do_open(http.client.HTTPSConnection, req,
           ^^^^^^^^^^^^^^^^^^^^^^^^^^^^^^^^^^^^^^^^^^^^^^
  File "/usr/lib/python3.12/urllib/request.py", line 1347, in do_open
    raise URLError(err)
urllib.error.URLError: <urlopen error [Errno -2] Name or service not known>
17/07/24 (20:02:17) | ERROR: Data collection thread failed with exception: Precision not allowed in integer format specifier
Traceback (most recent call last):
  File "/usr/bin/bpytop", line 2959, in _runner
    collector._draw()
  File "/usr/bin/bpytop", line 3991, in _draw
    ProcBox._draw_fg()
  File "/usr/bin/bpytop", line 2771, in _draw_fg
    (f'{proc.details["threads"]:^{iw}.{iw2}}' if expand > 0 else "") + (f'{proc.details["nice"]:^{iw}.{iw2}}' if expand > 1 else "") +
                                                                          ^^^^^^^^^^^^^^^^^^^^^^^^^^^^^^^^^^
ValueError: Precision not allowed in integer format specifier
17/07/24 (20:02:19) | WARNING: Exiting with errorcode (1). Runtime 3:55:27 

17/07/24 (20:02:21) | ERROR: <urlopen error [Errno -2] Name or service not known>
Traceback (most recent call last):
  File "/usr/lib/python3.12/urllib/request.py", line 1344, in do_open
    h.request(req.get_method(), req.selector, req.data, headers,
  File "/usr/lib/python3.12/http/client.py", line 1336, in request
    self._send_request(method, url, body, headers, encode_chunked)
  File "/usr/lib/python3.12/http/client.py", line 1382, in _send_request
    self.endheaders(body, encode_chunked=encode_chunked)
  File "/usr/lib/python3.12/http/client.py", line 1331, in endheaders
    self._send_output(message_body, encode_chunked=encode_chunked)
  File "/usr/lib/python3.12/http/client.py", line 1091, in _send_output
    self.send(msg)
  File "/usr/lib/python3.12/http/client.py", line 1035, in send
    self.connect()
  File "/usr/lib/python3.12/http/client.py", line 1470, in connect
    super().connect()
  File "/usr/lib/python3.12/http/client.py", line 1001, in connect
    self.sock = self._create_connection(
                ^^^^^^^^^^^^^^^^^^^^^^^^
  File "/usr/lib/python3.12/socket.py", line 829, in create_connection
    for res in getaddrinfo(host, port, 0, SOCK_STREAM):
               ^^^^^^^^^^^^^^^^^^^^^^^^^^^^^^^^^^^^^^^
  File "/usr/lib/python3.12/socket.py", line 964, in getaddrinfo
    for res in _socket.getaddrinfo(host, port, family, type, proto, flags):
               ^^^^^^^^^^^^^^^^^^^^^^^^^^^^^^^^^^^^^^^^^^^^^^^^^^^^^^^^^^^
socket.gaierror: [Errno -2] Name or service not known

During handling of the above exception, another exception occurred:

Traceback (most recent call last):
  File "/usr/bin/bpytop", line 5029, in _checker
    with urllib.request.urlopen("https://github.com/aristocratos/bpytop/raw/master/bpytop.py", timeout=5) as source: # type: ignore
         ^^^^^^^^^^^^^^^^^^^^^^^^^^^^^^^^^^^^^^^^^^^^^^^^^^^^^^^^^^^^^^^^^^^^^^^^^^^^^^^^^^^^^^^^^^^^^^^^
  File "/usr/lib/python3.12/urllib/request.py", line 215, in urlopen
    return opener.open(url, data, timeout)
           ^^^^^^^^^^^^^^^^^^^^^^^^^^^^^^^
  File "/usr/lib/python3.12/urllib/request.py", line 515, in open
    response = self._open(req, data)
               ^^^^^^^^^^^^^^^^^^^^^
  File "/usr/lib/python3.12/urllib/request.py", line 532, in _open
    result = self._call_chain(self.handle_open, protocol, protocol +
             ^^^^^^^^^^^^^^^^^^^^^^^^^^^^^^^^^^^^^^^^^^^^^^^^^^^^^^^
  File "/usr/lib/python3.12/urllib/request.py", line 492, in _call_chain
    result = func(*args)
             ^^^^^^^^^^^
  File "/usr/lib/python3.12/urllib/request.py", line 1392, in https_open
    return self.do_open(http.client.HTTPSConnection, req,
           ^^^^^^^^^^^^^^^^^^^^^^^^^^^^^^^^^^^^^^^^^^^^^^
  File "/usr/lib/python3.12/urllib/request.py", line 1347, in do_open
    raise URLError(err)
urllib.error.URLError: <urlopen error [Errno -2] Name or service not known>
18/07/24 (18:46:58) | ERROR: <urlopen error [Errno -2] Name or service not known>
Traceback (most recent call last):
  File "/usr/lib/python3.12/urllib/request.py", line 1344, in do_open
    h.request(req.get_method(), req.selector, req.data, headers,
  File "/usr/lib/python3.12/http/client.py", line 1336, in request
    self._send_request(method, url, body, headers, encode_chunked)
  File "/usr/lib/python3.12/http/client.py", line 1382, in _send_request
    self.endheaders(body, encode_chunked=encode_chunked)
  File "/usr/lib/python3.12/http/client.py", line 1331, in endheaders
    self._send_output(message_body, encode_chunked=encode_chunked)
  File "/usr/lib/python3.12/http/client.py", line 1091, in _send_output
    self.send(msg)
  File "/usr/lib/python3.12/http/client.py", line 1035, in send
    self.connect()
  File "/usr/lib/python3.12/http/client.py", line 1470, in connect
    super().connect()
  File "/usr/lib/python3.12/http/client.py", line 1001, in connect
    self.sock = self._create_connection(
                ^^^^^^^^^^^^^^^^^^^^^^^^
  File "/usr/lib/python3.12/socket.py", line 829, in create_connection
    for res in getaddrinfo(host, port, 0, SOCK_STREAM):
               ^^^^^^^^^^^^^^^^^^^^^^^^^^^^^^^^^^^^^^^
  File "/usr/lib/python3.12/socket.py", line 964, in getaddrinfo
    for res in _socket.getaddrinfo(host, port, family, type, proto, flags):
               ^^^^^^^^^^^^^^^^^^^^^^^^^^^^^^^^^^^^^^^^^^^^^^^^^^^^^^^^^^^
socket.gaierror: [Errno -2] Name or service not known

During handling of the above exception, another exception occurred:

Traceback (most recent call last):
  File "/usr/bin/bpytop", line 5029, in _checker
    with urllib.request.urlopen("https://github.com/aristocratos/bpytop/raw/master/bpytop.py", timeout=5) as source: # type: ignore
         ^^^^^^^^^^^^^^^^^^^^^^^^^^^^^^^^^^^^^^^^^^^^^^^^^^^^^^^^^^^^^^^^^^^^^^^^^^^^^^^^^^^^^^^^^^^^^^^^
  File "/usr/lib/python3.12/urllib/request.py", line 215, in urlopen
    return opener.open(url, data, timeout)
           ^^^^^^^^^^^^^^^^^^^^^^^^^^^^^^^
  File "/usr/lib/python3.12/urllib/request.py", line 515, in open
    response = self._open(req, data)
               ^^^^^^^^^^^^^^^^^^^^^
  File "/usr/lib/python3.12/urllib/request.py", line 532, in _open
    result = self._call_chain(self.handle_open, protocol, protocol +
             ^^^^^^^^^^^^^^^^^^^^^^^^^^^^^^^^^^^^^^^^^^^^^^^^^^^^^^^
  File "/usr/lib/python3.12/urllib/request.py", line 492, in _call_chain
    result = func(*args)
             ^^^^^^^^^^^
  File "/usr/lib/python3.12/urllib/request.py", line 1392, in https_open
    return self.do_open(http.client.HTTPSConnection, req,
           ^^^^^^^^^^^^^^^^^^^^^^^^^^^^^^^^^^^^^^^^^^^^^^
  File "/usr/lib/python3.12/urllib/request.py", line 1347, in do_open
    raise URLError(err)
urllib.error.URLError: <urlopen error [Errno -2] Name or service not known>
18/07/24 (18:48:32) | ERROR: Input thread failed with exception: [Errno 5] Input/output error
Traceback (most recent call last):
  File "/usr/bin/bpytop", line 957, in _get_key
    input_key += sys.stdin.read(1)						#* Read 1 key safely with blocking on
                 ^^^^^^^^^^^^^^^^^
OSError: [Errno 5] Input/output error
20/07/24 (16:43:46) | ERROR: Data collection thread failed with exception: Precision not allowed in integer format specifier
Traceback (most recent call last):
  File "/usr/bin/bpytop", line 2959, in _runner
    collector._draw()
  File "/usr/bin/bpytop", line 3991, in _draw
    ProcBox._draw_fg()
  File "/usr/bin/bpytop", line 2771, in _draw_fg
    (f'{proc.details["threads"]:^{iw}.{iw2}}' if expand > 0 else "") + (f'{proc.details["nice"]:^{iw}.{iw2}}' if expand > 1 else "") +
                                                                          ^^^^^^^^^^^^^^^^^^^^^^^^^^^^^^^^^^
ValueError: Precision not allowed in integer format specifier
26/07/24 (20:05:19) | ERROR: Data collection thread failed with exception: integer division or modulo by zero
Traceback (most recent call last):
  File "/usr/bin/bpytop", line 2959, in _runner
    collector._draw()
  File "/usr/bin/bpytop", line 3991, in _draw
    ProcBox._draw_fg()
  File "/usr/bin/bpytop", line 2834, in _draw_fg
    val = ((v if v <= 100 else 100) + 100) - calc * 100 // cls.select_max
                                             ~~~~~~~~~~~^^~~~~~~~~~~~~~~~
ZeroDivisionError: integer division or modulo by zero
26/07/24 (20:05:19) | WARNING: Exiting with errorcode (1). Runtime 0:00:00 

30/07/24 (11:43:28) | ERROR: Data collection thread failed with exception: Precision not allowed in integer format specifier
Traceback (most recent call last):
  File "/usr/bin/bpytop", line 2959, in _runner
    collector._draw()
  File "/usr/bin/bpytop", line 3991, in _draw
    ProcBox._draw_fg()
  File "/usr/bin/bpytop", line 2771, in _draw_fg
    (f'{proc.details["threads"]:^{iw}.{iw2}}' if expand > 0 else "") + (f'{proc.details["nice"]:^{iw}.{iw2}}' if expand > 1 else "") +
                                                                          ^^^^^^^^^^^^^^^^^^^^^^^^^^^^^^^^^^
ValueError: Precision not allowed in integer format specifier
01/08/24 (09:12:04) | ERROR: Data collection thread failed with exception: Precision not allowed in integer format specifier
Traceback (most recent call last):
  File "/usr/bin/bpytop", line 2959, in _runner
    collector._draw()
  File "/usr/bin/bpytop", line 3991, in _draw
    ProcBox._draw_fg()
  File "/usr/bin/bpytop", line 2771, in _draw_fg
    (f'{proc.details["threads"]:^{iw}.{iw2}}' if expand > 0 else "") + (f'{proc.details["nice"]:^{iw}.{iw2}}' if expand > 1 else "") +
                                                                          ^^^^^^^^^^^^^^^^^^^^^^^^^^^^^^^^^^
ValueError: Precision not allowed in integer format specifier
04/08/24 (13:55:46) | ERROR: <urlopen error [Errno -2] Name or service not known>
Traceback (most recent call last):
  File "/usr/lib/python3.12/urllib/request.py", line 1344, in do_open
    h.request(req.get_method(), req.selector, req.data, headers,
  File "/usr/lib/python3.12/http/client.py", line 1336, in request
    self._send_request(method, url, body, headers, encode_chunked)
  File "/usr/lib/python3.12/http/client.py", line 1382, in _send_request
    self.endheaders(body, encode_chunked=encode_chunked)
  File "/usr/lib/python3.12/http/client.py", line 1331, in endheaders
    self._send_output(message_body, encode_chunked=encode_chunked)
  File "/usr/lib/python3.12/http/client.py", line 1091, in _send_output
    self.send(msg)
  File "/usr/lib/python3.12/http/client.py", line 1035, in send
    self.connect()
  File "/usr/lib/python3.12/http/client.py", line 1470, in connect
    super().connect()
  File "/usr/lib/python3.12/http/client.py", line 1001, in connect
    self.sock = self._create_connection(
                ^^^^^^^^^^^^^^^^^^^^^^^^
  File "/usr/lib/python3.12/socket.py", line 829, in create_connection
    for res in getaddrinfo(host, port, 0, SOCK_STREAM):
               ^^^^^^^^^^^^^^^^^^^^^^^^^^^^^^^^^^^^^^^
  File "/usr/lib/python3.12/socket.py", line 964, in getaddrinfo
    for res in _socket.getaddrinfo(host, port, family, type, proto, flags):
               ^^^^^^^^^^^^^^^^^^^^^^^^^^^^^^^^^^^^^^^^^^^^^^^^^^^^^^^^^^^
socket.gaierror: [Errno -2] Name or service not known

During handling of the above exception, another exception occurred:

Traceback (most recent call last):
  File "/usr/bin/bpytop", line 5029, in _checker
    with urllib.request.urlopen("https://github.com/aristocratos/bpytop/raw/master/bpytop.py", timeout=5) as source: # type: ignore
         ^^^^^^^^^^^^^^^^^^^^^^^^^^^^^^^^^^^^^^^^^^^^^^^^^^^^^^^^^^^^^^^^^^^^^^^^^^^^^^^^^^^^^^^^^^^^^^^^
  File "/usr/lib/python3.12/urllib/request.py", line 215, in urlopen
    return opener.open(url, data, timeout)
           ^^^^^^^^^^^^^^^^^^^^^^^^^^^^^^^
  File "/usr/lib/python3.12/urllib/request.py", line 515, in open
    response = self._open(req, data)
               ^^^^^^^^^^^^^^^^^^^^^
  File "/usr/lib/python3.12/urllib/request.py", line 532, in _open
    result = self._call_chain(self.handle_open, protocol, protocol +
             ^^^^^^^^^^^^^^^^^^^^^^^^^^^^^^^^^^^^^^^^^^^^^^^^^^^^^^^
  File "/usr/lib/python3.12/urllib/request.py", line 492, in _call_chain
    result = func(*args)
             ^^^^^^^^^^^
  File "/usr/lib/python3.12/urllib/request.py", line 1392, in https_open
    return self.do_open(http.client.HTTPSConnection, req,
           ^^^^^^^^^^^^^^^^^^^^^^^^^^^^^^^^^^^^^^^^^^^^^^
  File "/usr/lib/python3.12/urllib/request.py", line 1347, in do_open
    raise URLError(err)
urllib.error.URLError: <urlopen error [Errno -2] Name or service not known>
09/08/24 (11:50:59) | ERROR: Data collection thread failed with exception: Sign not allowed in string format specifier
Traceback (most recent call last):
  File "/usr/bin/bpytop", line 2959, in _runner
    collector._draw()
  File "/usr/bin/bpytop", line 3991, in _draw
    ProcBox._draw_fg()
  File "/usr/bin/bpytop", line 2739, in _draw_fg
    label = (f'{THEME.title}{Fx.b}{Mv.to(y, x)}{"Pid:":>7} {"Program:" if prog_len > 8 else "Prg:":<{prog_len}}' + (f'{"Arguments:":<{arg_len-4}}' if arg_len else "") +
                                                           ^^^^^^^^^^^^^^^^^^^^^^^^^^^^^^^^^^^^^^^^^^^^^^^^^^^^
ValueError: Sign not allowed in string format specifier
09/08/24 (11:50:59) | WARNING: Exiting with errorcode (1). Runtime 0:00:00 

21/08/24 (15:26:06) | ERROR: Data collection thread failed with exception: 'pid'
Traceback (most recent call last):
  File "/usr/bin/bpytop", line 2959, in _runner
    collector._draw()
  File "/usr/bin/bpytop", line 3991, in _draw
    ProcBox._draw_fg()
  File "/usr/bin/bpytop", line 2638, in _draw_fg
    f'{Mv.to(dy-1, x+1)}{THEME.proc_box(Symbol.title_left)}{Fx.b}{THEME.title(str(proc.details["pid"]))}{Fx.ub}{THEME.proc_box(Symbol.title_right)}'
                                                                                  ~~~~~~~~~~~~^^^^^^^
KeyError: 'pid'
21/08/24 (15:26:08) | WARNING: Exiting with errorcode (1). Runtime 0:00:07 

21/08/24 (15:26:21) | ERROR: Data collection thread failed with exception: Precision not allowed in integer format specifier
Traceback (most recent call last):
  File "/usr/bin/bpytop", line 2959, in _runner
    collector._draw()
  File "/usr/bin/bpytop", line 3991, in _draw
    ProcBox._draw_fg()
  File "/usr/bin/bpytop", line 2771, in _draw_fg
    (f'{proc.details["threads"]:^{iw}.{iw2}}' if expand > 0 else "") + (f'{proc.details["nice"]:^{iw}.{iw2}}' if expand > 1 else "") +
                                                                          ^^^^^^^^^^^^^^^^^^^^^^^^^^^^^^^^^^
ValueError: Precision not allowed in integer format specifier
27/08/24 (12:55:41) | ERROR: <urlopen error _ssl.c:983: The handshake operation timed out>
Traceback (most recent call last):
  File "/usr/lib/python3.12/urllib/request.py", line 1344, in do_open
    h.request(req.get_method(), req.selector, req.data, headers,
  File "/usr/lib/python3.12/http/client.py", line 1336, in request
    self._send_request(method, url, body, headers, encode_chunked)
  File "/usr/lib/python3.12/http/client.py", line 1382, in _send_request
    self.endheaders(body, encode_chunked=encode_chunked)
  File "/usr/lib/python3.12/http/client.py", line 1331, in endheaders
    self._send_output(message_body, encode_chunked=encode_chunked)
  File "/usr/lib/python3.12/http/client.py", line 1091, in _send_output
    self.send(msg)
  File "/usr/lib/python3.12/http/client.py", line 1035, in send
    self.connect()
  File "/usr/lib/python3.12/http/client.py", line 1477, in connect
    self.sock = self._context.wrap_socket(self.sock,
                ^^^^^^^^^^^^^^^^^^^^^^^^^^^^^^^^^^^^
  File "/usr/lib/python3.12/ssl.py", line 455, in wrap_socket
    return self.sslsocket_class._create(
           ^^^^^^^^^^^^^^^^^^^^^^^^^^^^^
  File "/usr/lib/python3.12/ssl.py", line 1042, in _create
    self.do_handshake()
  File "/usr/lib/python3.12/ssl.py", line 1320, in do_handshake
    self._sslobj.do_handshake()
TimeoutError: _ssl.c:983: The handshake operation timed out

During handling of the above exception, another exception occurred:

Traceback (most recent call last):
  File "/usr/bin/bpytop", line 5029, in _checker
    with urllib.request.urlopen("https://github.com/aristocratos/bpytop/raw/master/bpytop.py", timeout=5) as source: # type: ignore
         ^^^^^^^^^^^^^^^^^^^^^^^^^^^^^^^^^^^^^^^^^^^^^^^^^^^^^^^^^^^^^^^^^^^^^^^^^^^^^^^^^^^^^^^^^^^^^^^^
  File "/usr/lib/python3.12/urllib/request.py", line 215, in urlopen
    return opener.open(url, data, timeout)
           ^^^^^^^^^^^^^^^^^^^^^^^^^^^^^^^
  File "/usr/lib/python3.12/urllib/request.py", line 515, in open
    response = self._open(req, data)
               ^^^^^^^^^^^^^^^^^^^^^
  File "/usr/lib/python3.12/urllib/request.py", line 532, in _open
    result = self._call_chain(self.handle_open, protocol, protocol +
             ^^^^^^^^^^^^^^^^^^^^^^^^^^^^^^^^^^^^^^^^^^^^^^^^^^^^^^^
  File "/usr/lib/python3.12/urllib/request.py", line 492, in _call_chain
    result = func(*args)
             ^^^^^^^^^^^
  File "/usr/lib/python3.12/urllib/request.py", line 1392, in https_open
    return self.do_open(http.client.HTTPSConnection, req,
           ^^^^^^^^^^^^^^^^^^^^^^^^^^^^^^^^^^^^^^^^^^^^^^
  File "/usr/lib/python3.12/urllib/request.py", line 1347, in do_open
    raise URLError(err)
urllib.error.URLError: <urlopen error _ssl.c:983: The handshake operation timed out>
27/08/24 (12:55:42) | ERROR: <urlopen error _ssl.c:983: The handshake operation timed out>
Traceback (most recent call last):
  File "/usr/lib/python3.12/urllib/request.py", line 1344, in do_open
    h.request(req.get_method(), req.selector, req.data, headers,
  File "/usr/lib/python3.12/http/client.py", line 1336, in request
    self._send_request(method, url, body, headers, encode_chunked)
  File "/usr/lib/python3.12/http/client.py", line 1382, in _send_request
    self.endheaders(body, encode_chunked=encode_chunked)
  File "/usr/lib/python3.12/http/client.py", line 1331, in endheaders
    self._send_output(message_body, encode_chunked=encode_chunked)
  File "/usr/lib/python3.12/http/client.py", line 1091, in _send_output
    self.send(msg)
  File "/usr/lib/python3.12/http/client.py", line 1035, in send
    self.connect()
  File "/usr/lib/python3.12/http/client.py", line 1477, in connect
    self.sock = self._context.wrap_socket(self.sock,
                ^^^^^^^^^^^^^^^^^^^^^^^^^^^^^^^^^^^^
  File "/usr/lib/python3.12/ssl.py", line 455, in wrap_socket
    return self.sslsocket_class._create(
           ^^^^^^^^^^^^^^^^^^^^^^^^^^^^^
  File "/usr/lib/python3.12/ssl.py", line 1042, in _create
    self.do_handshake()
  File "/usr/lib/python3.12/ssl.py", line 1320, in do_handshake
    self._sslobj.do_handshake()
TimeoutError: _ssl.c:983: The handshake operation timed out

During handling of the above exception, another exception occurred:

Traceback (most recent call last):
  File "/usr/bin/bpytop", line 5029, in _checker
    with urllib.request.urlopen("https://github.com/aristocratos/bpytop/raw/master/bpytop.py", timeout=5) as source: # type: ignore
         ^^^^^^^^^^^^^^^^^^^^^^^^^^^^^^^^^^^^^^^^^^^^^^^^^^^^^^^^^^^^^^^^^^^^^^^^^^^^^^^^^^^^^^^^^^^^^^^^
  File "/usr/lib/python3.12/urllib/request.py", line 215, in urlopen
    return opener.open(url, data, timeout)
           ^^^^^^^^^^^^^^^^^^^^^^^^^^^^^^^
  File "/usr/lib/python3.12/urllib/request.py", line 515, in open
    response = self._open(req, data)
               ^^^^^^^^^^^^^^^^^^^^^
  File "/usr/lib/python3.12/urllib/request.py", line 532, in _open
    result = self._call_chain(self.handle_open, protocol, protocol +
             ^^^^^^^^^^^^^^^^^^^^^^^^^^^^^^^^^^^^^^^^^^^^^^^^^^^^^^^
  File "/usr/lib/python3.12/urllib/request.py", line 492, in _call_chain
    result = func(*args)
             ^^^^^^^^^^^
  File "/usr/lib/python3.12/urllib/request.py", line 1392, in https_open
    return self.do_open(http.client.HTTPSConnection, req,
           ^^^^^^^^^^^^^^^^^^^^^^^^^^^^^^^^^^^^^^^^^^^^^^
  File "/usr/lib/python3.12/urllib/request.py", line 1347, in do_open
    raise URLError(err)
urllib.error.URLError: <urlopen error _ssl.c:983: The handshake operation timed out>
28/08/24 (13:30:35) | ERROR: <urlopen error [Errno -2] Name or service not known>
Traceback (most recent call last):
  File "/usr/lib/python3.12/urllib/request.py", line 1344, in do_open
    h.request(req.get_method(), req.selector, req.data, headers,
  File "/usr/lib/python3.12/http/client.py", line 1336, in request
    self._send_request(method, url, body, headers, encode_chunked)
  File "/usr/lib/python3.12/http/client.py", line 1382, in _send_request
    self.endheaders(body, encode_chunked=encode_chunked)
  File "/usr/lib/python3.12/http/client.py", line 1331, in endheaders
    self._send_output(message_body, encode_chunked=encode_chunked)
  File "/usr/lib/python3.12/http/client.py", line 1091, in _send_output
    self.send(msg)
  File "/usr/lib/python3.12/http/client.py", line 1035, in send
    self.connect()
  File "/usr/lib/python3.12/http/client.py", line 1470, in connect
    super().connect()
  File "/usr/lib/python3.12/http/client.py", line 1001, in connect
    self.sock = self._create_connection(
                ^^^^^^^^^^^^^^^^^^^^^^^^
  File "/usr/lib/python3.12/socket.py", line 829, in create_connection
    for res in getaddrinfo(host, port, 0, SOCK_STREAM):
               ^^^^^^^^^^^^^^^^^^^^^^^^^^^^^^^^^^^^^^^
  File "/usr/lib/python3.12/socket.py", line 964, in getaddrinfo
    for res in _socket.getaddrinfo(host, port, family, type, proto, flags):
               ^^^^^^^^^^^^^^^^^^^^^^^^^^^^^^^^^^^^^^^^^^^^^^^^^^^^^^^^^^^
socket.gaierror: [Errno -2] Name or service not known

During handling of the above exception, another exception occurred:

Traceback (most recent call last):
  File "/usr/bin/bpytop", line 5029, in _checker
    with urllib.request.urlopen("https://github.com/aristocratos/bpytop/raw/master/bpytop.py", timeout=5) as source: # type: ignore
         ^^^^^^^^^^^^^^^^^^^^^^^^^^^^^^^^^^^^^^^^^^^^^^^^^^^^^^^^^^^^^^^^^^^^^^^^^^^^^^^^^^^^^^^^^^^^^^^^
  File "/usr/lib/python3.12/urllib/request.py", line 215, in urlopen
    return opener.open(url, data, timeout)
           ^^^^^^^^^^^^^^^^^^^^^^^^^^^^^^^
  File "/usr/lib/python3.12/urllib/request.py", line 515, in open
    response = self._open(req, data)
               ^^^^^^^^^^^^^^^^^^^^^
  File "/usr/lib/python3.12/urllib/request.py", line 532, in _open
    result = self._call_chain(self.handle_open, protocol, protocol +
             ^^^^^^^^^^^^^^^^^^^^^^^^^^^^^^^^^^^^^^^^^^^^^^^^^^^^^^^
  File "/usr/lib/python3.12/urllib/request.py", line 492, in _call_chain
    result = func(*args)
             ^^^^^^^^^^^
  File "/usr/lib/python3.12/urllib/request.py", line 1392, in https_open
    return self.do_open(http.client.HTTPSConnection, req,
           ^^^^^^^^^^^^^^^^^^^^^^^^^^^^^^^^^^^^^^^^^^^^^^
  File "/usr/lib/python3.12/urllib/request.py", line 1347, in do_open
    raise URLError(err)
urllib.error.URLError: <urlopen error [Errno -2] Name or service not known>
28/08/24 (13:36:00) | ERROR: <urlopen error [Errno -2] Name or service not known>
Traceback (most recent call last):
  File "/usr/lib/python3.12/urllib/request.py", line 1344, in do_open
    h.request(req.get_method(), req.selector, req.data, headers,
  File "/usr/lib/python3.12/http/client.py", line 1336, in request
    self._send_request(method, url, body, headers, encode_chunked)
  File "/usr/lib/python3.12/http/client.py", line 1382, in _send_request
    self.endheaders(body, encode_chunked=encode_chunked)
  File "/usr/lib/python3.12/http/client.py", line 1331, in endheaders
    self._send_output(message_body, encode_chunked=encode_chunked)
  File "/usr/lib/python3.12/http/client.py", line 1091, in _send_output
    self.send(msg)
  File "/usr/lib/python3.12/http/client.py", line 1035, in send
    self.connect()
  File "/usr/lib/python3.12/http/client.py", line 1470, in connect
    super().connect()
  File "/usr/lib/python3.12/http/client.py", line 1001, in connect
    self.sock = self._create_connection(
                ^^^^^^^^^^^^^^^^^^^^^^^^
  File "/usr/lib/python3.12/socket.py", line 829, in create_connection
    for res in getaddrinfo(host, port, 0, SOCK_STREAM):
               ^^^^^^^^^^^^^^^^^^^^^^^^^^^^^^^^^^^^^^^
  File "/usr/lib/python3.12/socket.py", line 964, in getaddrinfo
    for res in _socket.getaddrinfo(host, port, family, type, proto, flags):
               ^^^^^^^^^^^^^^^^^^^^^^^^^^^^^^^^^^^^^^^^^^^^^^^^^^^^^^^^^^^
socket.gaierror: [Errno -2] Name or service not known

During handling of the above exception, another exception occurred:

Traceback (most recent call last):
  File "/usr/bin/bpytop", line 5029, in _checker
    with urllib.request.urlopen("https://github.com/aristocratos/bpytop/raw/master/bpytop.py", timeout=5) as source: # type: ignore
         ^^^^^^^^^^^^^^^^^^^^^^^^^^^^^^^^^^^^^^^^^^^^^^^^^^^^^^^^^^^^^^^^^^^^^^^^^^^^^^^^^^^^^^^^^^^^^^^^
  File "/usr/lib/python3.12/urllib/request.py", line 215, in urlopen
    return opener.open(url, data, timeout)
           ^^^^^^^^^^^^^^^^^^^^^^^^^^^^^^^
  File "/usr/lib/python3.12/urllib/request.py", line 515, in open
    response = self._open(req, data)
               ^^^^^^^^^^^^^^^^^^^^^
  File "/usr/lib/python3.12/urllib/request.py", line 532, in _open
    result = self._call_chain(self.handle_open, protocol, protocol +
             ^^^^^^^^^^^^^^^^^^^^^^^^^^^^^^^^^^^^^^^^^^^^^^^^^^^^^^^
  File "/usr/lib/python3.12/urllib/request.py", line 492, in _call_chain
    result = func(*args)
             ^^^^^^^^^^^
  File "/usr/lib/python3.12/urllib/request.py", line 1392, in https_open
    return self.do_open(http.client.HTTPSConnection, req,
           ^^^^^^^^^^^^^^^^^^^^^^^^^^^^^^^^^^^^^^^^^^^^^^
  File "/usr/lib/python3.12/urllib/request.py", line 1347, in do_open
    raise URLError(err)
urllib.error.URLError: <urlopen error [Errno -2] Name or service not known>
08/09/24 (22:47:32) | ERROR: Data collection thread failed with exception: list index out of range
Traceback (most recent call last):
  File "/usr/bin/bpytop", line 2959, in _runner
    collector._draw()
  File "/usr/bin/bpytop", line 3991, in _draw
    ProcBox._draw_fg()
  File "/usr/bin/bpytop", line 2835, in _draw_fg
    vals += [f'{THEME.gradient["proc_color" if val < 100 else "process"][val if val < 100 else val - 100]}']
                ~~~~~~~~~~~~~~~~~~~~~~~~~~~~~~~~~~~~~~~~~~~~~~~~~~~~~~~~^^^^^^^^^^^^^^^^^^^^^^^^^^^^^^^^^
IndexError: list index out of range
08/09/24 (22:47:32) | WARNING: Exiting with errorcode (1). Runtime 0:00:00 

25/11/24 (19:51:44) | ERROR: Data collection thread failed with exception: list index out of range
Traceback (most recent call last):
  File "/usr/bin/bpytop", line 2959, in _runner
    collector._draw()
  File "/usr/bin/bpytop", line 3991, in _draw
    ProcBox._draw_fg()
  File "/usr/bin/bpytop", line 2835, in _draw_fg
    vals += [f'{THEME.gradient["proc_color" if val < 100 else "process"][val if val < 100 else val - 100]}']
                ~~~~~~~~~~~~~~~~~~~~~~~~~~~~~~~~~~~~~~~~~~~~~~~~~~~~~~~~^^^^^^^^^^^^^^^^^^^^^^^^^^^^^^^^^
IndexError: list index out of range
25/11/24 (19:51:44) | WARNING: Exiting with errorcode (1). Runtime 0:00:00 

01/12/24 (11:07:06) | ERROR: <urlopen error [Errno -3] Temporary failure in name resolution>
Traceback (most recent call last):
  File "/usr/lib/python3.12/urllib/request.py", line 1344, in do_open
    h.request(req.get_method(), req.selector, req.data, headers,
  File "/usr/lib/python3.12/http/client.py", line 1336, in request
    self._send_request(method, url, body, headers, encode_chunked)
  File "/usr/lib/python3.12/http/client.py", line 1382, in _send_request
    self.endheaders(body, encode_chunked=encode_chunked)
  File "/usr/lib/python3.12/http/client.py", line 1331, in endheaders
    self._send_output(message_body, encode_chunked=encode_chunked)
  File "/usr/lib/python3.12/http/client.py", line 1091, in _send_output
    self.send(msg)
  File "/usr/lib/python3.12/http/client.py", line 1035, in send
    self.connect()
  File "/usr/lib/python3.12/http/client.py", line 1470, in connect
    super().connect()
  File "/usr/lib/python3.12/http/client.py", line 1001, in connect
    self.sock = self._create_connection(
                ^^^^^^^^^^^^^^^^^^^^^^^^
  File "/usr/lib/python3.12/socket.py", line 841, in create_connection
    for res in getaddrinfo(host, port, 0, SOCK_STREAM):
               ^^^^^^^^^^^^^^^^^^^^^^^^^^^^^^^^^^^^^^^
  File "/usr/lib/python3.12/socket.py", line 976, in getaddrinfo
    for res in _socket.getaddrinfo(host, port, family, type, proto, flags):
               ^^^^^^^^^^^^^^^^^^^^^^^^^^^^^^^^^^^^^^^^^^^^^^^^^^^^^^^^^^^
socket.gaierror: [Errno -3] Temporary failure in name resolution

During handling of the above exception, another exception occurred:

Traceback (most recent call last):
  File "/usr/bin/bpytop", line 5029, in _checker
    with urllib.request.urlopen("https://github.com/aristocratos/bpytop/raw/master/bpytop.py", timeout=5) as source: # type: ignore
         ^^^^^^^^^^^^^^^^^^^^^^^^^^^^^^^^^^^^^^^^^^^^^^^^^^^^^^^^^^^^^^^^^^^^^^^^^^^^^^^^^^^^^^^^^^^^^^^^
  File "/usr/lib/python3.12/urllib/request.py", line 215, in urlopen
    return opener.open(url, data, timeout)
           ^^^^^^^^^^^^^^^^^^^^^^^^^^^^^^^
  File "/usr/lib/python3.12/urllib/request.py", line 515, in open
    response = self._open(req, data)
               ^^^^^^^^^^^^^^^^^^^^^
  File "/usr/lib/python3.12/urllib/request.py", line 532, in _open
    result = self._call_chain(self.handle_open, protocol, protocol +
             ^^^^^^^^^^^^^^^^^^^^^^^^^^^^^^^^^^^^^^^^^^^^^^^^^^^^^^^
  File "/usr/lib/python3.12/urllib/request.py", line 492, in _call_chain
    result = func(*args)
             ^^^^^^^^^^^
  File "/usr/lib/python3.12/urllib/request.py", line 1392, in https_open
    return self.do_open(http.client.HTTPSConnection, req,
           ^^^^^^^^^^^^^^^^^^^^^^^^^^^^^^^^^^^^^^^^^^^^^^
  File "/usr/lib/python3.12/urllib/request.py", line 1347, in do_open
    raise URLError(err)
urllib.error.URLError: <urlopen error [Errno -3] Temporary failure in name resolution>
16/12/24 (10:48:41) | ERROR: Data collection thread failed with exception: list index out of range
Traceback (most recent call last):
  File "/usr/bin/bpytop", line 2959, in _runner
    collector._draw()
  File "/usr/bin/bpytop", line 3991, in _draw
    ProcBox._draw_fg()
  File "/usr/bin/bpytop", line 2835, in _draw_fg
    vals += [f'{THEME.gradient["proc_color" if val < 100 else "process"][val if val < 100 else val - 100]}']
                ~~~~~~~~~~~~~~~~~~~~~~~~~~~~~~~~~~~~~~~~~~~~~~~~~~~~~~~~^^^^^^^^^^^^^^^^^^^^^^^^^^^^^^^^^
IndexError: list index out of range
16/12/24 (10:48:41) | WARNING: Exiting with errorcode (1). Runtime 0:00:00 

22/12/24 (23:19:57) | ERROR: <urlopen error _ssl.c:983: The handshake operation timed out>
Traceback (most recent call last):
  File "/usr/lib/python3.12/urllib/request.py", line 1344, in do_open
    h.request(req.get_method(), req.selector, req.data, headers,
  File "/usr/lib/python3.12/http/client.py", line 1336, in request
    self._send_request(method, url, body, headers, encode_chunked)
  File "/usr/lib/python3.12/http/client.py", line 1382, in _send_request
    self.endheaders(body, encode_chunked=encode_chunked)
  File "/usr/lib/python3.12/http/client.py", line 1331, in endheaders
    self._send_output(message_body, encode_chunked=encode_chunked)
  File "/usr/lib/python3.12/http/client.py", line 1091, in _send_output
    self.send(msg)
  File "/usr/lib/python3.12/http/client.py", line 1035, in send
    self.connect()
  File "/usr/lib/python3.12/http/client.py", line 1477, in connect
    self.sock = self._context.wrap_socket(self.sock,
                ^^^^^^^^^^^^^^^^^^^^^^^^^^^^^^^^^^^^
  File "/usr/lib/python3.12/ssl.py", line 455, in wrap_socket
    return self.sslsocket_class._create(
           ^^^^^^^^^^^^^^^^^^^^^^^^^^^^^
  File "/usr/lib/python3.12/ssl.py", line 1041, in _create
    self.do_handshake()
  File "/usr/lib/python3.12/ssl.py", line 1319, in do_handshake
    self._sslobj.do_handshake()
TimeoutError: _ssl.c:983: The handshake operation timed out

During handling of the above exception, another exception occurred:

Traceback (most recent call last):
  File "/usr/bin/bpytop", line 5029, in _checker
    with urllib.request.urlopen("https://github.com/aristocratos/bpytop/raw/master/bpytop.py", timeout=5) as source: # type: ignore
         ^^^^^^^^^^^^^^^^^^^^^^^^^^^^^^^^^^^^^^^^^^^^^^^^^^^^^^^^^^^^^^^^^^^^^^^^^^^^^^^^^^^^^^^^^^^^^^^^
  File "/usr/lib/python3.12/urllib/request.py", line 215, in urlopen
    return opener.open(url, data, timeout)
           ^^^^^^^^^^^^^^^^^^^^^^^^^^^^^^^
  File "/usr/lib/python3.12/urllib/request.py", line 515, in open
    response = self._open(req, data)
               ^^^^^^^^^^^^^^^^^^^^^
  File "/usr/lib/python3.12/urllib/request.py", line 532, in _open
    result = self._call_chain(self.handle_open, protocol, protocol +
             ^^^^^^^^^^^^^^^^^^^^^^^^^^^^^^^^^^^^^^^^^^^^^^^^^^^^^^^
  File "/usr/lib/python3.12/urllib/request.py", line 492, in _call_chain
    result = func(*args)
             ^^^^^^^^^^^
  File "/usr/lib/python3.12/urllib/request.py", line 1392, in https_open
    return self.do_open(http.client.HTTPSConnection, req,
           ^^^^^^^^^^^^^^^^^^^^^^^^^^^^^^^^^^^^^^^^^^^^^^
  File "/usr/lib/python3.12/urllib/request.py", line 1347, in do_open
    raise URLError(err)
urllib.error.URLError: <urlopen error _ssl.c:983: The handshake operation timed out>
28/12/24 (02:32:04) | ERROR: Exception when sending signal 9 to pid 776
28/12/24 (02:32:04) | ERROR: [Errno 1] Operation not permitted
Traceback (most recent call last):
  File "/usr/bin/bpytop", line 5479, in process_keys
    os.kill(pid, sig)
PermissionError: [Errno 1] Operation not permitted
28/12/24 (02:32:11) | ERROR: Exception when sending signal 9 to pid 732
28/12/24 (02:32:11) | ERROR: [Errno 1] Operation not permitted
Traceback (most recent call last):
  File "/usr/bin/bpytop", line 5479, in process_keys
    os.kill(pid, sig)
PermissionError: [Errno 1] Operation not permitted
28/12/24 (02:32:15) | ERROR: Exception when sending signal 9 to pid 776
28/12/24 (02:32:15) | ERROR: [Errno 1] Operation not permitted
Traceback (most recent call last):
  File "/usr/bin/bpytop", line 5479, in process_keys
    os.kill(pid, sig)
PermissionError: [Errno 1] Operation not permitted
28/12/24 (02:32:15) | ERROR: Exception when sending signal 9 to pid 776
28/12/24 (02:32:15) | ERROR: [Errno 1] Operation not permitted
Traceback (most recent call last):
  File "/usr/bin/bpytop", line 5479, in process_keys
    os.kill(pid, sig)
PermissionError: [Errno 1] Operation not permitted
28/12/24 (02:32:22) | ERROR: Exception when sending signal 9 to pid 732
28/12/24 (02:32:22) | ERROR: [Errno 1] Operation not permitted
Traceback (most recent call last):
  File "/usr/bin/bpytop", line 5479, in process_keys
    os.kill(pid, sig)
PermissionError: [Errno 1] Operation not permitted
28/12/24 (02:32:23) | ERROR: Exception when sending signal 9 to pid 732
28/12/24 (02:32:23) | ERROR: [Errno 1] Operation not permitted
Traceback (most recent call last):
  File "/usr/bin/bpytop", line 5479, in process_keys
    os.kill(pid, sig)
PermissionError: [Errno 1] Operation not permitted
28/12/24 (02:32:24) | ERROR: Exception when sending signal 9 to pid 732
28/12/24 (02:32:24) | ERROR: [Errno 1] Operation not permitted
Traceback (most recent call last):
  File "/usr/bin/bpytop", line 5479, in process_keys
    os.kill(pid, sig)
PermissionError: [Errno 1] Operation not permitted
28/12/24 (02:32:27) | ERROR: Exception when sending signal 9 to pid 712
28/12/24 (02:32:27) | ERROR: [Errno 1] Operation not permitted
Traceback (most recent call last):
  File "/usr/bin/bpytop", line 5479, in process_keys
    os.kill(pid, sig)
PermissionError: [Errno 1] Operation not permitted
28/12/24 (02:32:30) | ERROR: Exception when sending signal 9 to pid 712
28/12/24 (02:32:30) | ERROR: [Errno 1] Operation not permitted
Traceback (most recent call last):
  File "/usr/bin/bpytop", line 5479, in process_keys
    os.kill(pid, sig)
PermissionError: [Errno 1] Operation not permitted
28/12/24 (02:32:36) | ERROR: Exception when sending signal 15 to pid 712
28/12/24 (02:32:36) | ERROR: [Errno 1] Operation not permitted
Traceback (most recent call last):
  File "/usr/bin/bpytop", line 5479, in process_keys
    os.kill(pid, sig)
PermissionError: [Errno 1] Operation not permitted
28/12/24 (02:32:38) | ERROR: Exception when sending signal 9 to pid 712
28/12/24 (02:32:38) | ERROR: [Errno 1] Operation not permitted
Traceback (most recent call last):
  File "/usr/bin/bpytop", line 5479, in process_keys
    os.kill(pid, sig)
PermissionError: [Errno 1] Operation not permitted
28/12/24 (02:32:39) | ERROR: Exception when sending signal 9 to pid 712
28/12/24 (02:32:39) | ERROR: [Errno 1] Operation not permitted
Traceback (most recent call last):
  File "/usr/bin/bpytop", line 5479, in process_keys
    os.kill(pid, sig)
PermissionError: [Errno 1] Operation not permitted
28/12/24 (02:33:02) | ERROR: Exception when sending signal 9 to pid 712
28/12/24 (02:33:02) | ERROR: [Errno 1] Operation not permitted
Traceback (most recent call last):
  File "/usr/bin/bpytop", line 5479, in process_keys
    os.kill(pid, sig)
PermissionError: [Errno 1] Operation not permitted
28/12/24 (02:33:03) | ERROR: Exception when sending signal 9 to pid 712
28/12/24 (02:33:03) | ERROR: [Errno 1] Operation not permitted
Traceback (most recent call last):
  File "/usr/bin/bpytop", line 5479, in process_keys
    os.kill(pid, sig)
PermissionError: [Errno 1] Operation not permitted
28/12/24 (02:33:04) | ERROR: Exception when sending signal 9 to pid 712
28/12/24 (02:33:04) | ERROR: [Errno 1] Operation not permitted
Traceback (most recent call last):
  File "/usr/bin/bpytop", line 5479, in process_keys
    os.kill(pid, sig)
PermissionError: [Errno 1] Operation not permitted
28/12/24 (02:33:04) | ERROR: Exception when sending signal 9 to pid 712
28/12/24 (02:33:04) | ERROR: [Errno 1] Operation not permitted
Traceback (most recent call last):
  File "/usr/bin/bpytop", line 5479, in process_keys
    os.kill(pid, sig)
PermissionError: [Errno 1] Operation not permitted
28/12/24 (02:33:18) | ERROR: Exception when sending signal 9 to pid 732
28/12/24 (02:33:18) | ERROR: [Errno 1] Operation not permitted
Traceback (most recent call last):
  File "/usr/bin/bpytop", line 5479, in process_keys
    os.kill(pid, sig)
PermissionError: [Errno 1] Operation not permitted
28/12/24 (02:33:21) | ERROR: Exception when sending signal 9 to pid 732
28/12/24 (02:33:21) | ERROR: [Errno 1] Operation not permitted
Traceback (most recent call last):
  File "/usr/bin/bpytop", line 5479, in process_keys
    os.kill(pid, sig)
PermissionError: [Errno 1] Operation not permitted
28/12/24 (02:33:23) | ERROR: Exception when sending signal 9 to pid 732
28/12/24 (02:33:23) | ERROR: [Errno 1] Operation not permitted
Traceback (most recent call last):
  File "/usr/bin/bpytop", line 5479, in process_keys
    os.kill(pid, sig)
PermissionError: [Errno 1] Operation not permitted
28/12/24 (03:14:07) | ERROR: Exception when sending signal 9 to pid 683
28/12/24 (03:14:07) | ERROR: [Errno 1] Operation not permitted
Traceback (most recent call last):
  File "/usr/bin/bpytop", line 5479, in process_keys
    os.kill(pid, sig)
PermissionError: [Errno 1] Operation not permitted
31/12/24 (16:39:29) | ERROR: Data collection thread failed with exception: list index out of range
Traceback (most recent call last):
  File "/usr/bin/bpytop", line 2959, in _runner
    collector._draw()
  File "/usr/bin/bpytop", line 3991, in _draw
    ProcBox._draw_fg()
  File "/usr/bin/bpytop", line 2835, in _draw_fg
    vals += [f'{THEME.gradient["proc_color" if val < 100 else "process"][val if val < 100 else val - 100]}']
                ~~~~~~~~~~~~~~~~~~~~~~~~~~~~~~~~~~~~~~~~~~~~~~~~~~~~~~~~^^^^^^^^^^^^^^^^^^^^^^^^^^^^^^^^^
IndexError: list index out of range
31/12/24 (16:39:29) | WARNING: Exiting with errorcode (1). Runtime 0:00:00 

07/01/25 (04:32:32) | ERROR: Data collection thread failed with exception: integer division or modulo by zero
Traceback (most recent call last):
  File "/usr/bin/bpytop", line 2959, in _runner
    collector._draw()
    ~~~~~~~~~~~~~~~^^
  File "/usr/bin/bpytop", line 3991, in _draw
    ProcBox._draw_fg()
    ~~~~~~~~~~~~~~~~^^
  File "/usr/bin/bpytop", line 2834, in _draw_fg
    val = ((v if v <= 100 else 100) + 100) - calc * 100 // cls.select_max
                                             ~~~~~~~~~~~^^~~~~~~~~~~~~~~~
ZeroDivisionError: integer division or modulo by zero
07/01/25 (04:32:32) | WARNING: Exiting with errorcode (1). Runtime 0:00:00 

07/01/25 (23:14:14) | ERROR: Data collection thread failed with exception: Sign not allowed in string format specifier
Traceback (most recent call last):
  File "/usr/bin/bpytop", line 2959, in _runner
    collector._draw()
    ~~~~~~~~~~~~~~~^^
  File "/usr/bin/bpytop", line 3991, in _draw
    ProcBox._draw_fg()
    ~~~~~~~~~~~~~~~~^^
  File "/usr/bin/bpytop", line 2739, in _draw_fg
    label = (f'{THEME.title}{Fx.b}{Mv.to(y, x)}{"Pid:":>7} {"Program:" if prog_len > 8 else "Prg:":<{prog_len}}' + (f'{"Arguments:":<{arg_len-4}}' if arg_len else "") +
                                                           ^^^^^^^^^^^^^^^^^^^^^^^^^^^^^^^^^^^^^^^^^^^^^^^^^^^^
ValueError: Sign not allowed in string format specifier
07/01/25 (23:14:14) | WARNING: Exiting with errorcode (1). Runtime 0:00:00 

07/01/25 (23:14:15) | ERROR: Remote end closed connection without response
Traceback (most recent call last):
  File "/usr/bin/bpytop", line 5029, in _checker
    with urllib.request.urlopen("https://github.com/aristocratos/bpytop/raw/master/bpytop.py", timeout=5) as source: # type: ignore
         ~~~~~~~~~~~~~~~~~~~~~~^^^^^^^^^^^^^^^^^^^^^^^^^^^^^^^^^^^^^^^^^^^^^^^^^^^^^^^^^^^^^^^^^^^^^^^^^^
  File "/usr/lib/python3.13/urllib/request.py", line 189, in urlopen
    return opener.open(url, data, timeout)
           ~~~~~~~~~~~^^^^^^^^^^^^^^^^^^^^
  File "/usr/lib/python3.13/urllib/request.py", line 489, in open
    response = self._open(req, data)
  File "/usr/lib/python3.13/urllib/request.py", line 506, in _open
    result = self._call_chain(self.handle_open, protocol, protocol +
                              '_open', req)
  File "/usr/lib/python3.13/urllib/request.py", line 466, in _call_chain
    result = func(*args)
  File "/usr/lib/python3.13/urllib/request.py", line 1367, in https_open
    return self.do_open(http.client.HTTPSConnection, req,
           ~~~~~~~~~~~~^^^^^^^^^^^^^^^^^^^^^^^^^^^^^^^^^^
                        context=self._context)
                        ^^^^^^^^^^^^^^^^^^^^^^
  File "/usr/lib/python3.13/urllib/request.py", line 1323, in do_open
    r = h.getresponse()
  File "/usr/lib/python3.13/http/client.py", line 1428, in getresponse
    response.begin()
    ~~~~~~~~~~~~~~^^
  File "/usr/lib/python3.13/http/client.py", line 331, in begin
    version, status, reason = self._read_status()
                              ~~~~~~~~~~~~~~~~~^^
  File "/usr/lib/python3.13/http/client.py", line 300, in _read_status
    raise RemoteDisconnected("Remote end closed connection without"
                             " response")
http.client.RemoteDisconnected: Remote end closed connection without response
07/01/25 (23:14:16) | ERROR: Data collection thread failed with exception: Sign not allowed in string format specifier
Traceback (most recent call last):
  File "/usr/bin/bpytop", line 2959, in _runner
    collector._draw()
    ~~~~~~~~~~~~~~~^^
  File "/usr/bin/bpytop", line 3991, in _draw
    ProcBox._draw_fg()
    ~~~~~~~~~~~~~~~~^^
  File "/usr/bin/bpytop", line 2739, in _draw_fg
    label = (f'{THEME.title}{Fx.b}{Mv.to(y, x)}{"Pid:":>7} {"Program:" if prog_len > 8 else "Prg:":<{prog_len}}' + (f'{"Arguments:":<{arg_len-4}}' if arg_len else "") +
                                                           ^^^^^^^^^^^^^^^^^^^^^^^^^^^^^^^^^^^^^^^^^^^^^^^^^^^^
ValueError: Sign not allowed in string format specifier
07/01/25 (23:14:16) | WARNING: Exiting with errorcode (1). Runtime 0:00:00 

07/01/25 (23:24:56) | ERROR: Data collection thread failed with exception: Sign not allowed in string format specifier
Traceback (most recent call last):
  File "/usr/bin/bpytop", line 2959, in _runner
    collector._draw()
    ~~~~~~~~~~~~~~~^^
  File "/usr/bin/bpytop", line 3991, in _draw
    ProcBox._draw_fg()
    ~~~~~~~~~~~~~~~~^^
  File "/usr/bin/bpytop", line 2739, in _draw_fg
    label = (f'{THEME.title}{Fx.b}{Mv.to(y, x)}{"Pid:":>7} {"Program:" if prog_len > 8 else "Prg:":<{prog_len}}' + (f'{"Arguments:":<{arg_len-4}}' if arg_len else "") +
                                                           ^^^^^^^^^^^^^^^^^^^^^^^^^^^^^^^^^^^^^^^^^^^^^^^^^^^^
ValueError: Sign not allowed in string format specifier
07/01/25 (23:24:57) | WARNING: Exiting with errorcode (1). Runtime 0:00:52 

11/01/25 (21:42:44) | ERROR: <urlopen error [Errno -3] Temporary failure in name resolution>
Traceback (most recent call last):
  File "/usr/lib/python3.13/urllib/request.py", line 1319, in do_open
    h.request(req.get_method(), req.selector, req.data, headers,
    ~~~~~~~~~^^^^^^^^^^^^^^^^^^^^^^^^^^^^^^^^^^^^^^^^^^^^^^^^^^^
              encode_chunked=req.has_header('Transfer-encoding'))
              ^^^^^^^^^^^^^^^^^^^^^^^^^^^^^^^^^^^^^^^^^^^^^^^^^^^
  File "/usr/lib/python3.13/http/client.py", line 1336, in request
    self._send_request(method, url, body, headers, encode_chunked)
    ~~~~~~~~~~~~~~~~~~^^^^^^^^^^^^^^^^^^^^^^^^^^^^^^^^^^^^^^^^^^^^
  File "/usr/lib/python3.13/http/client.py", line 1382, in _send_request
    self.endheaders(body, encode_chunked=encode_chunked)
    ~~~~~~~~~~~~~~~^^^^^^^^^^^^^^^^^^^^^^^^^^^^^^^^^^^^^
  File "/usr/lib/python3.13/http/client.py", line 1331, in endheaders
    self._send_output(message_body, encode_chunked=encode_chunked)
    ~~~~~~~~~~~~~~~~~^^^^^^^^^^^^^^^^^^^^^^^^^^^^^^^^^^^^^^^^^^^^^
  File "/usr/lib/python3.13/http/client.py", line 1091, in _send_output
    self.send(msg)
    ~~~~~~~~~^^^^^
  File "/usr/lib/python3.13/http/client.py", line 1035, in send
    self.connect()
    ~~~~~~~~~~~~^^
  File "/usr/lib/python3.13/http/client.py", line 1470, in connect
    super().connect()
    ~~~~~~~~~~~~~~~^^
  File "/usr/lib/python3.13/http/client.py", line 1001, in connect
    self.sock = self._create_connection(
                ~~~~~~~~~~~~~~~~~~~~~~~^
        (self.host,self.port), self.timeout, self.source_address)
        ^^^^^^^^^^^^^^^^^^^^^^^^^^^^^^^^^^^^^^^^^^^^^^^^^^^^^^^^^
  File "/usr/lib/python3.13/socket.py", line 840, in create_connection
    for res in getaddrinfo(host, port, 0, SOCK_STREAM):
               ~~~~~~~~~~~^^^^^^^^^^^^^^^^^^^^^^^^^^^^
  File "/usr/lib/python3.13/socket.py", line 975, in getaddrinfo
    for res in _socket.getaddrinfo(host, port, family, type, proto, flags):
               ~~~~~~~~~~~~~~~~~~~^^^^^^^^^^^^^^^^^^^^^^^^^^^^^^^^^^^^^^^^
socket.gaierror: [Errno -3] Temporary failure in name resolution

During handling of the above exception, another exception occurred:

Traceback (most recent call last):
  File "/usr/bin/bpytop", line 5029, in _checker
    with urllib.request.urlopen("https://github.com/aristocratos/bpytop/raw/master/bpytop.py", timeout=5) as source: # type: ignore
         ~~~~~~~~~~~~~~~~~~~~~~^^^^^^^^^^^^^^^^^^^^^^^^^^^^^^^^^^^^^^^^^^^^^^^^^^^^^^^^^^^^^^^^^^^^^^^^^^
  File "/usr/lib/python3.13/urllib/request.py", line 189, in urlopen
    return opener.open(url, data, timeout)
           ~~~~~~~~~~~^^^^^^^^^^^^^^^^^^^^
  File "/usr/lib/python3.13/urllib/request.py", line 489, in open
    response = self._open(req, data)
  File "/usr/lib/python3.13/urllib/request.py", line 506, in _open
    result = self._call_chain(self.handle_open, protocol, protocol +
                              '_open', req)
  File "/usr/lib/python3.13/urllib/request.py", line 466, in _call_chain
    result = func(*args)
  File "/usr/lib/python3.13/urllib/request.py", line 1367, in https_open
    return self.do_open(http.client.HTTPSConnection, req,
           ~~~~~~~~~~~~^^^^^^^^^^^^^^^^^^^^^^^^^^^^^^^^^^
                        context=self._context)
                        ^^^^^^^^^^^^^^^^^^^^^^
  File "/usr/lib/python3.13/urllib/request.py", line 1322, in do_open
    raise URLError(err)
urllib.error.URLError: <urlopen error [Errno -3] Temporary failure in name resolution>
11/01/25 (21:42:47) | ERROR: <urlopen error [Errno -3] Temporary failure in name resolution>
Traceback (most recent call last):
  File "/usr/lib/python3.13/urllib/request.py", line 1319, in do_open
    h.request(req.get_method(), req.selector, req.data, headers,
    ~~~~~~~~~^^^^^^^^^^^^^^^^^^^^^^^^^^^^^^^^^^^^^^^^^^^^^^^^^^^
              encode_chunked=req.has_header('Transfer-encoding'))
              ^^^^^^^^^^^^^^^^^^^^^^^^^^^^^^^^^^^^^^^^^^^^^^^^^^^
  File "/usr/lib/python3.13/http/client.py", line 1336, in request
    self._send_request(method, url, body, headers, encode_chunked)
    ~~~~~~~~~~~~~~~~~~^^^^^^^^^^^^^^^^^^^^^^^^^^^^^^^^^^^^^^^^^^^^
  File "/usr/lib/python3.13/http/client.py", line 1382, in _send_request
    self.endheaders(body, encode_chunked=encode_chunked)
    ~~~~~~~~~~~~~~~^^^^^^^^^^^^^^^^^^^^^^^^^^^^^^^^^^^^^
  File "/usr/lib/python3.13/http/client.py", line 1331, in endheaders
    self._send_output(message_body, encode_chunked=encode_chunked)
    ~~~~~~~~~~~~~~~~~^^^^^^^^^^^^^^^^^^^^^^^^^^^^^^^^^^^^^^^^^^^^^
  File "/usr/lib/python3.13/http/client.py", line 1091, in _send_output
    self.send(msg)
    ~~~~~~~~~^^^^^
  File "/usr/lib/python3.13/http/client.py", line 1035, in send
    self.connect()
    ~~~~~~~~~~~~^^
  File "/usr/lib/python3.13/http/client.py", line 1470, in connect
    super().connect()
    ~~~~~~~~~~~~~~~^^
  File "/usr/lib/python3.13/http/client.py", line 1001, in connect
    self.sock = self._create_connection(
                ~~~~~~~~~~~~~~~~~~~~~~~^
        (self.host,self.port), self.timeout, self.source_address)
        ^^^^^^^^^^^^^^^^^^^^^^^^^^^^^^^^^^^^^^^^^^^^^^^^^^^^^^^^^
  File "/usr/lib/python3.13/socket.py", line 840, in create_connection
    for res in getaddrinfo(host, port, 0, SOCK_STREAM):
               ~~~~~~~~~~~^^^^^^^^^^^^^^^^^^^^^^^^^^^^
  File "/usr/lib/python3.13/socket.py", line 975, in getaddrinfo
    for res in _socket.getaddrinfo(host, port, family, type, proto, flags):
               ~~~~~~~~~~~~~~~~~~~^^^^^^^^^^^^^^^^^^^^^^^^^^^^^^^^^^^^^^^^
socket.gaierror: [Errno -3] Temporary failure in name resolution

During handling of the above exception, another exception occurred:

Traceback (most recent call last):
  File "/usr/bin/bpytop", line 5029, in _checker
    with urllib.request.urlopen("https://github.com/aristocratos/bpytop/raw/master/bpytop.py", timeout=5) as source: # type: ignore
         ~~~~~~~~~~~~~~~~~~~~~~^^^^^^^^^^^^^^^^^^^^^^^^^^^^^^^^^^^^^^^^^^^^^^^^^^^^^^^^^^^^^^^^^^^^^^^^^^
  File "/usr/lib/python3.13/urllib/request.py", line 189, in urlopen
    return opener.open(url, data, timeout)
           ~~~~~~~~~~~^^^^^^^^^^^^^^^^^^^^
  File "/usr/lib/python3.13/urllib/request.py", line 489, in open
    response = self._open(req, data)
  File "/usr/lib/python3.13/urllib/request.py", line 506, in _open
    result = self._call_chain(self.handle_open, protocol, protocol +
                              '_open', req)
  File "/usr/lib/python3.13/urllib/request.py", line 466, in _call_chain
    result = func(*args)
  File "/usr/lib/python3.13/urllib/request.py", line 1367, in https_open
    return self.do_open(http.client.HTTPSConnection, req,
           ~~~~~~~~~~~~^^^^^^^^^^^^^^^^^^^^^^^^^^^^^^^^^^
                        context=self._context)
                        ^^^^^^^^^^^^^^^^^^^^^^
  File "/usr/lib/python3.13/urllib/request.py", line 1322, in do_open
    raise URLError(err)
urllib.error.URLError: <urlopen error [Errno -3] Temporary failure in name resolution>
19/02/25 (17:31:57) | ERROR: Data collection thread failed with exception: 'io_read'
Traceback (most recent call last):
  File "/usr/bin/bpytop", line 2959, in _runner
    collector._draw()
    ~~~~~~~~~~~~~~~^^
  File "/usr/bin/bpytop", line 3991, in _draw
    ProcBox._draw_fg()
    ~~~~~~~~~~~~~~~~^^
  File "/usr/bin/bpytop", line 2772, in _draw_fg
    (f'{proc.details["io_read"]:^{iw}.{iw2}}' if expand > 2 else "") + (f'{proc.details["io_write"]:^{iw}.{iw2}}' if expand > 3 else "") +
        ~~~~~~~~~~~~^^^^^^^^^^^
KeyError: 'io_read'
19/02/25 (17:31:58) | WARNING: Exiting with errorcode (1). Runtime 0:00:07 

14/04/25 (09:25:49) | ERROR: <urlopen error [Errno -3] Temporary failure in name resolution>
Traceback (most recent call last):
  File "/usr/lib/python3.13/urllib/request.py", line 1319, in do_open
    h.request(req.get_method(), req.selector, req.data, headers,
    ~~~~~~~~~^^^^^^^^^^^^^^^^^^^^^^^^^^^^^^^^^^^^^^^^^^^^^^^^^^^
              encode_chunked=req.has_header('Transfer-encoding'))
              ^^^^^^^^^^^^^^^^^^^^^^^^^^^^^^^^^^^^^^^^^^^^^^^^^^^
  File "/usr/lib/python3.13/http/client.py", line 1338, in request
    self._send_request(method, url, body, headers, encode_chunked)
    ~~~~~~~~~~~~~~~~~~^^^^^^^^^^^^^^^^^^^^^^^^^^^^^^^^^^^^^^^^^^^^
  File "/usr/lib/python3.13/http/client.py", line 1384, in _send_request
    self.endheaders(body, encode_chunked=encode_chunked)
    ~~~~~~~~~~~~~~~^^^^^^^^^^^^^^^^^^^^^^^^^^^^^^^^^^^^^
  File "/usr/lib/python3.13/http/client.py", line 1333, in endheaders
    self._send_output(message_body, encode_chunked=encode_chunked)
    ~~~~~~~~~~~~~~~~~^^^^^^^^^^^^^^^^^^^^^^^^^^^^^^^^^^^^^^^^^^^^^
  File "/usr/lib/python3.13/http/client.py", line 1093, in _send_output
    self.send(msg)
    ~~~~~~~~~^^^^^
  File "/usr/lib/python3.13/http/client.py", line 1037, in send
    self.connect()
    ~~~~~~~~~~~~^^
  File "/usr/lib/python3.13/http/client.py", line 1472, in connect
    super().connect()
    ~~~~~~~~~~~~~~~^^
  File "/usr/lib/python3.13/http/client.py", line 1003, in connect
    self.sock = self._create_connection(
                ~~~~~~~~~~~~~~~~~~~~~~~^
        (self.host,self.port), self.timeout, self.source_address)
        ^^^^^^^^^^^^^^^^^^^^^^^^^^^^^^^^^^^^^^^^^^^^^^^^^^^^^^^^^
  File "/usr/lib/python3.13/socket.py", line 840, in create_connection
    for res in getaddrinfo(host, port, 0, SOCK_STREAM):
               ~~~~~~~~~~~^^^^^^^^^^^^^^^^^^^^^^^^^^^^
  File "/usr/lib/python3.13/socket.py", line 977, in getaddrinfo
    for res in _socket.getaddrinfo(host, port, family, type, proto, flags):
               ~~~~~~~~~~~~~~~~~~~^^^^^^^^^^^^^^^^^^^^^^^^^^^^^^^^^^^^^^^^
socket.gaierror: [Errno -3] Temporary failure in name resolution

During handling of the above exception, another exception occurred:

Traceback (most recent call last):
  File "/usr/bin/bpytop", line 5029, in _checker
    with urllib.request.urlopen("https://github.com/aristocratos/bpytop/raw/master/bpytop.py", timeout=5) as source: # type: ignore
         ~~~~~~~~~~~~~~~~~~~~~~^^^^^^^^^^^^^^^^^^^^^^^^^^^^^^^^^^^^^^^^^^^^^^^^^^^^^^^^^^^^^^^^^^^^^^^^^^
  File "/usr/lib/python3.13/urllib/request.py", line 189, in urlopen
    return opener.open(url, data, timeout)
           ~~~~~~~~~~~^^^^^^^^^^^^^^^^^^^^
  File "/usr/lib/python3.13/urllib/request.py", line 489, in open
    response = self._open(req, data)
  File "/usr/lib/python3.13/urllib/request.py", line 506, in _open
    result = self._call_chain(self.handle_open, protocol, protocol +
                              '_open', req)
  File "/usr/lib/python3.13/urllib/request.py", line 466, in _call_chain
    result = func(*args)
  File "/usr/lib/python3.13/urllib/request.py", line 1367, in https_open
    return self.do_open(http.client.HTTPSConnection, req,
           ~~~~~~~~~~~~^^^^^^^^^^^^^^^^^^^^^^^^^^^^^^^^^^
                        context=self._context)
                        ^^^^^^^^^^^^^^^^^^^^^^
  File "/usr/lib/python3.13/urllib/request.py", line 1322, in do_open
    raise URLError(err)
urllib.error.URLError: <urlopen error [Errno -3] Temporary failure in name resolution>
14/04/25 (09:25:53) | ERROR: Input thread failed with exception: [Errno 5] Input/output error
Traceback (most recent call last):
  File "/usr/bin/bpytop", line 957, in _get_key
    input_key += sys.stdin.read(1)						#* Read 1 key safely with blocking on
                 ~~~~~~~~~~~~~~^^^
OSError: [Errno 5] Input/output error
